ERROR:cfscanner.main:Error in starting xray service.
multiprocessing.pool.RemoteTraceback: 
"""
Traceback (most recent call last):
  File "/home/smz/.local/lib/python3.10/site-packages/cfscanner/speedtest/conduct.py", line 95, in test_ip
    process, proxies = start_proxy_service(
  File "/home/smz/.local/lib/python3.10/site-packages/cfscanner/xray/service.py", line 26, in start_proxy_service
    proxy_listen = proxy_conf["inbounds"][0]["listen"]
KeyError: 'listen'

During handling of the above exception, another exception occurred:

Traceback (most recent call last):
  File "/usr/lib/python3.10/multiprocessing/pool.py", line 125, in worker
    result = (True, func(*args, **kwds))
  File "/home/smz/.local/lib/python3.10/site-packages/cfscanner/speedtest/conduct.py", line 102, in test_ip
    raise StartProxyServiceError(
cfscanner.utils.exceptions.StartProxyServiceError: Could not start xray service - 104.27.41.239
"""

The above exception was the direct cause of the following exception:

Traceback (most recent call last):
  File "/home/smz/.local/lib/python3.10/site-packages/cfscanner/main.py", line 218, in main
    res = next(iterator)
  File "/usr/lib/python3.10/multiprocessing/pool.py", line 873, in next
    raise value
cfscanner.utils.exceptions.StartProxyServiceError: Could not start xray service - 104.27.41.239
